Workbook

Sheet 0_عن_المشروع
A1: تحليل مبيعات متجر نوفا للإلكترونيات - 2024
A4: مشروع تحليل بيانات شامل من الصفر باستخدام Microsoft Excel | إعداد: محلل بيانات | 2024
A6: المشكلة التجارية / السياق
A7: متجر "نوفا" للإلكترونيات سلسلة تجزئة سعودية تدير 5 فروع (الرياض، جدة، الدمام، مكة المكرمة، المدينة المنورة). تحتاج إدارة المبيعات إلى فهم أداء عام 2024 عبر الفروع والفئات والمندوبين وطرق الدفع وأنواع العملاء، لاتخاذ قرارات مبنية على بيانات بخصوص المخزون، الحملات التسويقية، وخطط الحوافز للمندوبين للعام القادم.
A8: أسئلة العمل التي يجيب عنها هذا الملف: ما أكثر الفئات والمنتجات ربحية؟ أي الفروع والمناطق الأعلى أداءً؟ كيف تتغير المبيعات موسميًا؟ ما الفرق بين سلوك عملاء الأفراد والشركات؟ وأين تكمن فرص النمو والتحسين؟
A10: مصدر البيانات ونطاقها
A11: بيانات مبيعات محاكاة (Synthetic) لكنها مبنية على أنماط واقعية (موسمية، توزيع أسعار، سلوك عملاء) لتمثيل تصدير خام نموذجي من نظام نقاط بيع لعام كامل (2024)، شاملة 1,196 سجل معاملة خام قبل التنظيف و1,120 سجلًا بعد التنظيف.
A13: أدوات ومنهجية العمل
A14: Microsoft Excel بالكامل: جداول Excel (Tables) منظمة، دوال (SUMIFS, COUNTIFS, AVERAGEIFS, INDEX, MATCH, LARGE, SUMPRODUCT, IFERROR, ROUNDUP...)، تنسيق شرطي، قوائم تحقق من صحة البيانات (Data Validation) كفلاتر تفاعلية، ومخططات Excel أصلية (عمودي، خطي، دائري، Donut).
A16: دليل شيتات الملف
A17: الشيت | C17: المحتوى
A18: Dashboard | C18: لوحة التحكم التفاعلية الرئيسية: مؤشرات ومخططات تتحدث تلقائيًا حسب فلاتر المنطقة والفئة.
A19: Charts | C19: 6 مخططات تحليلية شاملة لعام 2024 عبر مختلف الأبعاد (فئة، فرع، شهر، منتج، دفع، مندوب).
A20: Summary_Tables | C20: 8 جداول تحليلية/تلخيصية مبنية بالكامل على معادلات حية (بديل الجداول المحورية).
A21: Insights_Recommendations | C21: أهم الرؤى والاستنتاجات والتوصيات العملية المبنية على التحليل.
A22: Clean_Data | C22: البيانات بعد التنظيف الكامل (1,120 صفًا) مع أعمدة محسوبة بالمعادلات (المنطقة، الشهر، الإجمالي...).
A23: Cleaning_Log | C23: توثيق كامل لخطوات التنظيف مع أعداد حية لكل مشكلة تم اكتشافها ومعالجتها.
A24: Raw_Data | C24: البيانات الخام كما وردت (1,196 صفًا) مع أعمدة فحص جودة حية تُبرز المشاكل قبل التنظيف.
A26: ملاحظة منهجية
A27: تم تعمّد استخدام جداول تلخيصية بمعادلات (SUMIFS/COUNTIFS/LARGE/INDEX-MATCH) بدلاً من جداول PivotTable الثابتة، وقوائم تحقق من صحة البيانات (Data Validation) كفلاتر تفاعلية بدلاً من Slicers التقليدية، لضمان أن يبقى الملف قابلاً لإعادة الحساب الكامل تلقائيًا وبدون أي أخطاء مهما كان البرنامج المستخدم لفتحه (Excel أو بدائله)، مع الحفاظ على نفس تجربة التفاعل والتحديث الفوري.

Sheet Dashboard
A1: لوحة تحكم مبيعات متجر نوفا للإلكترونيات - 2024
A2: لوحة تفاعلية: غيّر الفلاتر أدناه لتحديث كل المؤشرات والمخططات تلقائيًا
A4: المنطقة: | B4: الكل | D4: الفئة: | E4: الكل | G4: 💡 استخدم القائمتين المنسدلتين على اليمين لتصفية جميع المؤشرات والمخططات في هذه اللوحة فورًا دون الحاجة لأي إجراء إضافي.
A7: إجمالي المبيعات (ر.س) | C7: عدد الطلبات | E7: متوسط قيمة الطلب | G7: إجمالي الوحدات المباعة | I7: % من إجمالي مبيعات السنة
A8: =SUMIFS(CleanData[إجمالي المبيعات],CleanData[المنطقة],IF($B$4="الكل","*",$B$4),CleanData[الفئة],IF($E$4="الكل","*",$E$4)) -> 3698240.9 | C8: =COUNTIFS(CleanData[المنطقة],IF($B$4="الكل","*",$B$4),CleanData[الفئة],IF($E$4="الكل","*",$E$4)) -> 1120 | E8: =IFERROR(A8/C8,0) -> 3302.0008 | G8: =SUMIFS(CleanData[الكمية],CleanData[المنطقة],IF($B$4="الكل","*",$B$4),CleanData[الفئة],IF($E$4="الكل","*",$E$4)) -> 2085 | I8: =IFERROR(A8/SUM(CleanData[إجمالي المبيعات]),0) -> 1
A10: بيانات الرسوم البيانية (تتحدث تلقائيًا حسب الفلاتر أعلاه)
A11: الشهر | B11: المبيعات | D11: الفرع | E11: المبيعات | G11: نوع العميل | H11: المبيعات | J11: طريقة الدفع | K11: المبيعات
A12: يناير | B12: =SUMIFS(CleanData[إجمالي المبيعات],CleanData[اسم الشهر],$A12,CleanData[المنطقة],IF($B$4="الكل","*",$B$4),CleanData[الفئة],IF($E$4="الكل","*",$E$4)) -> 245455.7 | D12: الرياض | E12: =SUMIFS(CleanData[إجمالي المبيعات],CleanData[الفرع],$D12,CleanData[المنطقة],IF($B$4="الكل","*",$B$4),CleanData[الفئة],IF($E$4="الكل","*",$E$4)) -> 1133402.8 | G12: فرد | H12: =SUMIFS(CleanData[إجمالي المبيعات],CleanData[نوع العميل],$G12,CleanData[المنطقة],IF($B$4="الكل","*",$B$4),CleanData[الفئة],IF($E$4="الكل","*",$E$4)) -> 2097433.2 | J12: بطاقة ائتمان | K12: =SUMIFS(CleanData[إجمالي المبيعات],CleanData[طريقة الدفع],$J12,CleanData[المنطقة],IF($B$4="الكل","*",$B$4),CleanData[الفئة],IF($E$4="الكل","*",$E$4)) -> 1605693.6
A13: فبراير | B13: =SUMIFS(CleanData[إجمالي المبيعات],CleanData[اسم الشهر],$A13,CleanData[المنطقة],IF($B$4="الكل","*",$B$4),CleanData[الفئة],IF($E$4="الكل","*",$E$4)) -> 230319.15 | D13: جدة | E13: =SUMIFS(CleanData[إجمالي المبيعات],CleanData[الفرع],$D13,CleanData[المنطقة],IF($B$4="الكل","*",$B$4),CleanData[الفئة],IF($E$4="الكل","*",$E$4)) -> 1105399.2 | G13: شركة | H13: =SUMIFS(CleanData[إجمالي المبيعات],CleanData[نوع العميل],$G13,CleanData[المنطقة],IF($B$4="الكل","*",$B$4),CleanData[الفئة],IF($E$4="الكل","*",$E$4)) -> 1600807.7 | J13: نقدي | K13: =SUMIFS(CleanData[إجمالي المبيعات],CleanData[طريقة الدفع],$J13,CleanData[المنطقة],IF($B$4="الكل","*",$B$4),CleanData[الفئة],IF($E$4="الكل","*",$E$4)) -> 994640.75
A14: مارس | B14: =SUMIFS(CleanData[إجمالي المبيعات],CleanData[اسم الشهر],$A14,CleanData[المنطقة],IF($B$4="الكل","*",$B$4),CleanData[الفئة],IF($E$4="الكل","*",$E$4)) -> 310641.8 | D14: الدمام | E14: =SUMIFS(CleanData[إجمالي المبيعات],CleanData[الفرع],$D14,CleanData[المنطقة],IF($B$4="الكل","*",$B$4),CleanData[الفئة],IF($E$4="الكل","*",$E$4)) -> 517668.4 | J14: تقسيط | K14: =SUMIFS(CleanData[إجمالي المبيعات],CleanData[طريقة الدفع],$J14,CleanData[المنطقة],IF($B$4="الكل","*",$B$4),CleanData[الفئة],IF($E$4="الكل","*",$E$4)) -> 747593.95
A15: أبريل | B15: =SUMIFS(CleanData[إجمالي المبيعات],CleanData[اسم الشهر],$A15,CleanData[المنطقة],IF($B$4="الكل","*",$B$4),CleanData[الفئة],IF($E$4="الكل","*",$E$4)) -> 197125.5 | D15: مكة المكرمة | E15: =SUMIFS(CleanData[إجمالي المبيعات],CleanData[الفرع],$D15,CleanData[المنطقة],IF($B$4="الكل","*",$B$4),CleanData[الفئة],IF($E$4="الكل","*",$E$4)) -> 444396.8 | J15: تحويل بنكي | K15: =SUMIFS(CleanData[إجمالي المبيعات],CleanData[طريقة الدفع],$J15,CleanData[المنطقة],IF($B$4="الكل","*",$B$4),CleanData[الفئة],IF($E$4="الكل","*",$E$4)) -> 350312.55
A16: مايو | B16: =SUMIFS(CleanData[إجمالي المبيعات],CleanData[اسم الشهر],$A16,CleanData[المنطقة],IF($B$4="الكل","*",$B$4),CleanData[الفئة],IF($E$4="الكل","*",$E$4)) -> 341120.65 | D16: المدينة المنورة | E16: =SUMIFS(CleanData[إجمالي المبيعات],CleanData[الفرع],$D16,CleanData[المنطقة],IF($B$4="الكل","*",$B$4),CleanData[الفئة],IF($E$4="الكل","*",$E$4)) -> 497373.7
A17: يونيو | B17: =SUMIFS(CleanData[إجمالي المبيعات],CleanData[اسم الشهر],$A17,CleanData[المنطقة],IF($B$4="الكل","*",$B$4),CleanData[الفئة],IF($E$4="الكل","*",$E$4)) -> 427179.65
A18: يوليو | B18: =SUMIFS(CleanData[إجمالي المبيعات],CleanData[اسم الشهر],$A18,CleanData[المنطقة],IF($B$4="الكل","*",$B$4),CleanData[الفئة],IF($E$4="الكل","*",$E$4)) -> 242251.65
A19: أغسطس | B19: =SUMIFS(CleanData[إجمالي المبيعات],CleanData[اسم الشهر],$A19,CleanData[المنطقة],IF($B$4="الكل","*",$B$4),CleanData[الفئة],IF($E$4="الكل","*",$E$4)) -> 329999.7
A20: سبتمبر | B20: =SUMIFS(CleanData[إجمالي المبيعات],CleanData[اسم الشهر],$A20,CleanData[المنطقة],IF($B$4="الكل","*",$B$4),CleanData[الفئة],IF($E$4="الكل","*",$E$4)) -> 229364.75
A21: أكتوبر | B21: =SUMIFS(CleanData[إجمالي المبيعات],CleanData[اسم الشهر],$A21,CleanData[المنطقة],IF($B$4="الكل","*",$B$4),CleanData[الفئة],IF($E$4="الكل","*",$E$4)) -> 383931.85
A22: نوفمبر | B22: =SUMIFS(CleanData[إجمالي المبيعات],CleanData[اسم الشهر],$A22,CleanData[المنطقة],IF($B$4="الكل","*",$B$4),CleanData[الفئة],IF($E$4="الكل","*",$E$4)) -> 431308.7
A23: ديسمبر | B23: =SUMIFS(CleanData[إجمالي المبيعات],CleanData[اسم الشهر],$A23,CleanData[المنطقة],IF($B$4="الكل","*",$B$4),CleanData[الفئة],IF($E$4="الكل","*",$E$4)) -> 329541.8
A25: المخططات التفاعلية (تعكس الفلاتر المختارة أعلاه)

Sheet Charts
A1: المخططات التحليلية
A2: نظرة عامة على أداء المبيعات لعام 2024 عبر مختلف الأبعاد

Sheet Summary_Tables
A1: الجداول التحليلية الملخصة
A2: جداول تلخيصية ديناميكية مبنية بالكامل على معادلات Excel (SUMIFS / COUNTIFS / AVERAGEIFS / LARGE / INDEX-MATCH)
H3: مساعد: إجمالي مبيعات كل مندوب (لا يُعرض للمستخدم مباشرة) | K3: مساعد: إجمالي مبيعات كل منتج
A4: 1) مؤشرات الأداء الرئيسية لعام 2024 | H4: تركي السبيعي | I4: =SUMIFS(CleanData[إجمالي المبيعات],CleanData[المندوب],$H4) -> 280521.3 | K4: باور بانك 20000 | L4: =SUMIFS(CleanData[إجمالي المبيعات],CleanData[المنتج],$K4) -> 25822.7
A5: إجمالي المبيعات (ر.س) | B5: =SUM(CleanData[إجمالي المبيعات]) -> 3698240.9 | H5: خالد الشمري | I5: =SUMIFS(CleanData[إجمالي المبيعات],CleanData[المندوب],$H5) -> 352945.65 | K5: جوال أوركا الجديد | L5: =SUMIFS(CleanData[إجمالي المبيعات],CleanData[المنتج],$K5) -> 387741.65
A6: إجمالي عدد الطلبات | B6: =COUNTA(CleanData[رقم الطلب]) -> 1120 | H6: ريم الزهراني | I6: =SUMIFS(CleanData[إجمالي المبيعات],CleanData[المندوب],$H6) -> 369894.05 | K6: جوال أوركا برو | L6: =SUMIFS(CleanData[إجمالي المبيعات],CleanData[المنتج],$K6) -> 292850.3
A7: متوسط قيمة الطلب (ر.س) | B7: =AVERAGE(CleanData[إجمالي المبيعات]) -> 3302.0008 | H7: سارة القحطاني | I7: =SUMIFS(CleanData[إجمالي المبيعات],CleanData[المندوب],$H7) -> 518419.35 | K7: جوال بولسار ميني | L7: =SUMIFS(CleanData[إجمالي المبيعات],CleanData[المنتج],$K7) -> 278878.4
A8: إجمالي الوحدات المباعة | B8: =SUM(CleanData[الكمية]) -> 2085 | H8: عبدالله المطيري | I8: =SUMIFS(CleanData[إجمالي المبيعات],CleanData[المندوب],$H8) -> 494190.6 | K8: جوال نوفا X12 | L8: =SUMIFS(CleanData[إجمالي المبيعات],CleanData[المنتج],$K8) -> 438135.45
A9: متوسط نسبة الخصم | B9: =AVERAGE(CleanData[نسبة الخصم]) -> 0.049151786 | H9: فهد الغامدي | I9: =SUMIFS(CleanData[إجمالي المبيعات],CleanData[المندوب],$H9) -> 383783.8 | K9: جوال نوفا لايت | L9: =SUMIFS(CleanData[إجمالي المبيعات],CleanData[المنتج],$K9) -> 373808.75
A10: إجمالي قيمة الخصومات الممنوحة (ر.س) | B10: =SUMPRODUCT(CleanData[سعر الوحدة]*CleanData[الكمية]*CleanData[نسبة الخصم]) -> 187984.1 | H10: لمى العنزي | I10: =SUMIFS(CleanData[إجمالي المبيعات],CleanData[المندوب],$H10) -> 270669.8 | K10: حامل جوال للسيارة | L10: =SUMIFS(CleanData[إجمالي المبيعات],CleanData[المنتج],$K10) -> 15411.15
H11: محمد العتيبي | I11: =SUMIFS(CleanData[إجمالي المبيعات],CleanData[المندوب],$H11) -> 420906.6 | K11: سماعة بلوتوث نوفا | L11: =SUMIFS(CleanData[إجمالي المبيعات],CleanData[المنتج],$K11) -> 33438.95
H12: منيرة الحربي | I12: =SUMIFS(CleanData[إجمالي المبيعات],CleanData[المندوب],$H12) -> 252109.5 | K12: سماعة رأس أوركا | L12: =SUMIFS(CleanData[إجمالي المبيعات],CleanData[المنتج],$K12) -> 40584.25
A13: 2) المبيعات حسب فئة المنتج | H13: نورة الدوسري | I13: =SUMIFS(CleanData[إجمالي المبيعات],CleanData[المندوب],$H13) -> 354800.25 | K13: سماعة رياضية مقاومة للماء | L13: =SUMIFS(CleanData[إجمالي المبيعات],CleanData[المنتج],$K13) -> 28973.95
A14: الفئة | B14: إجمالي المبيعات | C14: عدد الطلبات | D14: متوسط قيمة الطلب | E14: % من إجمالي المبيعات | K14: شاحن سريع 65 واط | L14: =SUMIFS(CleanData[إجمالي المبيعات],CleanData[المنتج],$K14) -> 17831.3
A15: جوالات | B15: =SUMIFS(CleanData[إجمالي المبيعات],CleanData[الفئة],$A15) -> 1771414.6 | C15: =COUNTIFS(CleanData[الفئة],$A15) -> 356 | D15: =IFERROR(B15/C15,0) -> 4975.8836 | E15: =B15/$B$5 -> 0.47898842 | K15: كابل شحن Type-C | L15: =SUMIFS(CleanData[إجمالي المبيعات],CleanData[المنتج],$K15) -> 15904.55
A16: حواسيب محمولة | B16: =SUMIFS(CleanData[إجمالي المبيعات],CleanData[الفئة],$A16) -> 1623912.8 | C16: =COUNTIFS(CleanData[الفئة],$A16) -> 196 | D16: =IFERROR(B16/C16,0) -> 8285.2691 | E16: =B16/$B$5 -> 0.4391041 | K16: كاميرا مراقبة ذكية | L16: =SUMIFS(CleanData[إجمالي المبيعات],CleanData[المنتج],$K16) -> 17428.75
A17: إكسسوارات | B17: =SUMIFS(CleanData[إجمالي المبيعات],CleanData[الفئة],$A17) -> 91278.95 | C17: =COUNTIFS(CleanData[الفئة],$A17) -> 279 | D17: =IFERROR(B17/C17,0) -> 327.1647 | E17: =B17/$B$5 -> 0.024681721 | K17: كفر حماية بريميوم | L17: =SUMIFS(CleanData[إجمالي المبيعات],CleanData[المنتج],$K17) -> 16309.25
A18: أجهزة منزلية ذكية | B18: =SUMIFS(CleanData[إجمالي المبيعات],CleanData[الفئة],$A18) -> 69917.3 | C18: =COUNTIFS(CleanData[الفئة],$A18) -> 126 | D18: =IFERROR(B18/C18,0) -> 554.89921 | E18: =B18/$B$5 -> 0.018905556 | K18: لابتوب أوركا برو 15 | L18: =SUMIFS(CleanData[إجمالي المبيعات],CleanData[المنتج],$K18) -> 484250.9
A19: سماعات وصوتيات | B19: =SUMIFS(CleanData[إجمالي المبيعات],CleanData[الفئة],$A19) -> 141717.35 | C19: =COUNTIFS(CleanData[الفئة],$A19) -> 163 | D19: =IFERROR(B19/C19,0) -> 869.4316 | E19: =B19/$B$5 -> 0.038320205 | K19: لابتوب بولسار الأساسي | L19: =SUMIFS(CleanData[إجمالي المبيعات],CleanData[المنتج],$K19) -> 329267.65
K20: لابتوب نوفا ألترا | L20: =SUMIFS(CleanData[إجمالي المبيعات],CleanData[المنتج],$K20) -> 385404.5
K21: لابتوب نوفا بوك 14 | L21: =SUMIFS(CleanData[إجمالي المبيعات],CleanData[المنتج],$K21) -> 424989.7
A22: 3) المبيعات حسب الفرع والمنطقة | K22: مصباح ذكي | L22: =SUMIFS(CleanData[إجمالي المبيعات],CleanData[المنتج],$K22) -> 18835.35
A23: الفرع | B23: المنطقة | C23: إجمالي المبيعات | D23: عدد الطلبات | E23: متوسط قيمة الطلب | K23: مقبس كهرباء ذكي | L23: =SUMIFS(CleanData[إجمالي المبيعات],CleanData[المنتج],$K23) -> 16872.85
A24: الرياض | B24: =INDEX(Lists!$B$2:$B$6,MATCH($A24,Lists!$A$2:$A$6,0)) -> المنطقة الوسطى | C24: =SUMIFS(CleanData[إجمالي المبيعات],CleanData[الفرع],$A24) -> 1133402.8 | D24: =COUNTIFS(CleanData[الفرع],$A24) -> 361 | E24: =IFERROR(C24/D24,0) -> 3139.6199 | K24: مكبر صوت محمول | L24: =SUMIFS(CleanData[إجمالي المبيعات],CleanData[المنتج],$K24) -> 38720.2
A25: جدة | B25: =INDEX(Lists!$B$2:$B$6,MATCH($A25,Lists!$A$2:$A$6,0)) -> المنطقة الغربية | C25: =SUMIFS(CleanData[إجمالي المبيعات],CleanData[الفرع],$A25) -> 1105399.2 | D25: =COUNTIFS(CleanData[الفرع],$A25) -> 311 | E25: =IFERROR(C25/D25,0) -> 3554.3383 | K25: مكبر صوت منزلي ذكي | L25: =SUMIFS(CleanData[إجمالي المبيعات],CleanData[المنتج],$K25) -> 16780.35
A26: الدمام | B26: =INDEX(Lists!$B$2:$B$6,MATCH($A26,Lists!$A$2:$A$6,0)) -> المنطقة الشرقية | C26: =SUMIFS(CleanData[إجمالي المبيعات],CleanData[الفرع],$A26) -> 517668.4 | D26: =COUNTIFS(CleanData[الفرع],$A26) -> 165 | E26: =IFERROR(C26/D26,0) -> 3137.3842
A27: مكة المكرمة | B27: =INDEX(Lists!$B$2:$B$6,MATCH($A27,Lists!$A$2:$A$6,0)) -> المنطقة الغربية | C27: =SUMIFS(CleanData[إجمالي المبيعات],CleanData[الفرع],$A27) -> 444396.8 | D27: =COUNTIFS(CleanData[الفرع],$A27) -> 144 | E27: =IFERROR(C27/D27,0) -> 3086.0889
A28: المدينة المنورة | B28: =INDEX(Lists!$B$2:$B$6,MATCH($A28,Lists!$A$2:$A$6,0)) -> المنطقة الغربية | C28: =SUMIFS(CleanData[إجمالي المبيعات],CleanData[الفرع],$A28) -> 497373.7 | D28: =COUNTIFS(CleanData[الفرع],$A28) -> 139 | E28: =IFERROR(C28/D28,0) -> 3578.2281
A31: 4) الاتجاه الشهري للمبيعات (2024)
A32: الشهر | B32: إجمالي المبيعات | C32: عدد الطلبات | D32: متوسط قيمة الطلب
A33: يناير | B33: =SUMIFS(CleanData[إجمالي المبيعات],CleanData[اسم الشهر],$A33) -> 245455.7 | C33: =COUNTIFS(CleanData[اسم الشهر],$A33) -> 81 | D33: =IFERROR(B33/C33,0) -> 3030.3173
A34: فبراير | B34: =SUMIFS(CleanData[إجمالي المبيعات],CleanData[اسم الشهر],$A34) -> 230319.15 | C34: =COUNTIFS(CleanData[اسم الشهر],$A34) -> 70 | D34: =IFERROR(B34/C34,0) -> 3290.2736
A35: مارس | B35: =SUMIFS(CleanData[إجمالي المبيعات],CleanData[اسم الشهر],$A35) -> 310641.8 | C35: =COUNTIFS(CleanData[اسم الشهر],$A35) -> 103 | D35: =IFERROR(B35/C35,0) -> 3015.9398
A36: أبريل | B36: =SUMIFS(CleanData[إجمالي المبيعات],CleanData[اسم الشهر],$A36) -> 197125.5 | C36: =COUNTIFS(CleanData[اسم الشهر],$A36) -> 68 | D36: =IFERROR(B36/C36,0) -> 2898.9044
A37: مايو | B37: =SUMIFS(CleanData[إجمالي المبيعات],CleanData[اسم الشهر],$A37) -> 341120.65 | C37: =COUNTIFS(CleanData[اسم الشهر],$A37) -> 84 | D37: =IFERROR(B37/C37,0) -> 4060.9601
A38: يونيو | B38: =SUMIFS(CleanData[إجمالي المبيعات],CleanData[اسم الشهر],$A38) -> 427179.65 | C38: =COUNTIFS(CleanData[اسم الشهر],$A38) -> 90 | D38: =IFERROR(B38/C38,0) -> 4746.4406
A39: يوليو | B39: =SUMIFS(CleanData[إجمالي المبيعات],CleanData[اسم الشهر],$A39) -> 242251.65 | C39: =COUNTIFS(CleanData[اسم الشهر],$A39) -> 85 | D39: =IFERROR(B39/C39,0) -> 2850.0194
A40: أغسطس | B40: =SUMIFS(CleanData[إجمالي المبيعات],CleanData[اسم الشهر],$A40) -> 329999.7 | C40: =COUNTIFS(CleanData[اسم الشهر],$A40) -> 121 | D40: =IFERROR(B40/C40,0) -> 2727.2702
A41: سبتمبر | B41: =SUMIFS(CleanData[إجمالي المبيعات],CleanData[اسم الشهر],$A41) -> 229364.75 | C41: =COUNTIFS(CleanData[اسم الشهر],$A41) -> 78 | D41: =IFERROR(B41/C41,0) -> 2940.5737
A42: أكتوبر | B42: =SUMIFS(CleanData[إجمالي المبيعات],CleanData[اسم الشهر],$A42) -> 383931.85 | C42: =COUNTIFS(CleanData[اسم الشهر],$A42) -> 96 | D42: =IFERROR(B42/C42,0) -> 3999.2901
...

Sheet Insights_Recommendations
A1: الرؤى والاستنتاجات والتوصيات
A2: خلاصة تحليلية لأداء مبيعات عام 2024 وتوصيات عملية قابلة للتنفيذ
A4: 1) أهم الرؤى والأنماط المستخرجة من البيانات
A5: • بلغ إجمالي مبيعات عام 2024 نحو 3,698,241 ر.س عبر 1,120 طلبًا نظيفًا، بمتوسط قيمة طلب 3,302 ر.س ومتوسط خصم فعلي 4.9% فقط.
A6: • فئتا الجوالات والحواسيب المحمولة تستحوذان معًا على نحو 92% من إجمالي المبيعات (48% و44% على التوالي)، بينما تساهم الإكسسوارات والأجهزة المنزلية الذكية والسماعات مجتمعة بأقل من 8% رغم تمثيلها لغالبية عدد الطلبات (568 من أصل 1,120) — أي أنها فئات عالية الحجم ومنخفضة القيمة.
A7: • فرعا الرياض وجدة يتصدران المبيعات بفارق طفيف (1.13 مليون و1.11 مليون ر.س)، ويمثلان معًا 61% من إجمالي المبيعات، بينما فروع الدمام والمدينة المنورة ومكة المكرمة متقاربة في الأداء (444-518 ألف ر.س لكل منها).
A8: • شهرا نوفمبر ويونيو هما الأعلى مبيعًا (431 ألفًا و427 ألف ر.س)، ما يعكس أثر عروض الجمعة البيضاء ومناسبات الصيف؛ بينما أبريل هو الأضعف (197 ألف ر.س) - فارق يقارب 118% بين أعلى وأدنى شهر.
A9: • عملاء الشركات يمثلون 21% فقط من عدد الطلبات (234 طلبًا) لكنهم يساهمون بـ 43% من إجمالي المبيعات (1.6 مليون ر.س)، بمتوسط قيمة طلب 6,841 ر.س - أي نحو 2.9 ضعف متوسط طلب الأفراد (2,367 ر.س).
A10: • الدفع بالبطاقة الائتمانية هو الأكثر استخدامًا (43% من المبيعات)، يليه النقدي (27%) ثم التقسيط (20%)؛ التحويل البنكي هو الأقل استخدامًا (9%) رغم كونه الأنسب لعملاء الشركات الكبار.
A11: • أفضل مندوب مبيعات (سارة القحطاني) حقق 518 ألف ر.س، بفارق يقارب 106% عن أقل مندوب أداءً (منيرة الحربي، 252 ألف ر.س) - فجوة كبيرة تستحق المراجعة.
A12: • أفضل 5 منتجات مبيعًا كلها من فئتي الجوالات والحواسيب المحمولة (يتصدرها لابتوب أوركا برو 15 بمبيعات 484 ألف ر.س)، ما يؤكد اعتماد المتجر الكبير على عدد محدود من المنتجات ذات القيمة العالية.
A14: 2) الاستنتاجات الرئيسية
... A30: جميع الأرقام أعلاه مستخرجة مباشرة من شيتي 'Clean_Data' و'Summary_Tables' في هذا الملف عبر معادلات حيّة (SUMIFS/COUNTIFS/AVERAGEIFS)، ويمكن التحقق منها أو إعادة حسابها تلقائيًا في حال تحديث البيانات المصدر.

Sheet Clean_Data
A1: رقم الطلب | B1: تاريخ الطلب | C1: السنة | D1: رقم الشهر | E1: اسم الشهر | F1: الربع | G1: اسم اليوم | H1: الفرع | I1: المنطقة | J1: الفئة | K1: المنتج | L1: سعر الوحدة | M1: الكمية | N1: نسبة الخصم | O1: طريقة الدفع | P1: نوع العميل | Q1: المندوب | R1: إجمالي المبيعات
A2: ORD-00002 | B2: 45292 | C2: =YEAR(B2) -> 2024 | D2: =MONTH(B2) -> 1 | E2: =INDEX(Lists!$K$2:$K$13,MATCH(D2,Lists!$J$2:$J$13,0)) -> يناير | F2: ="Q"&ROUNDUP(D2/3,0) -> Q1 | G2: =INDEX(Lists!$N$2:$N$8,MATCH(WEEKDAY(B2,2),Lists!$M$2:$M$8,0)) -> الإثنين | H2: المدينة المنورة | I2: =INDEX(Lists!$B$2:$B$6,MATCH(H2,Lists!$A$2:$A$6,0)) -> المنطقة الغربية | J2: سماعات وصوتيات | K2: مكبر صوت محمول | L2: 679 | M2: 1 | N2: 0 | O2: تقسيط | P2: فرد | Q2: ريم الزهراني | R2: =L2*M2*(1-N2) -> 679
A3: ORD-00001 | B3: 45292 | C3: =YEAR(B3) -> 2024 | D3: =MONTH(B3) -> 1 | E3: =INDEX(Lists!$K$2:$K$13,MATCH(D3,Lists!$J$2:$J$13,0)) -> يناير | F3: ="Q"&ROUNDUP(D3/3,0) -> Q1 | G3: =INDEX(Lists!$N$2:$N$8,MATCH(WEEKDAY(B3,2),Lists!$M$2:$M$8,0)) -> الإثنين | H3: مكة المكرمة | I3: =INDEX(Lists!$B$2:$B$6,MATCH(H3,Lists!$A$2:$A$6,0)) -> المنطقة الغربية | J3: جوالات | K3: جوال بولسار ميني | L3: 1509 | M3: 1 | N3: 0 | O3: بطاقة ائتمان | P3: فرد | Q3: ريم الزهراني | R3: =L3*M3*(1-N3) -> 1509
A4: ORD-00003 | B4: 45293 | C4: =YEAR(B4) -> 2024 | D4: =MONTH(B4) -> 1 | E4: =INDEX(Lists!$K$2:$K$13,MATCH(D4,Lists!$J$2:$J$13,0)) -> يناير | F4: ="Q"&ROUNDUP(D4/3,0) -> Q1 | G4: =INDEX(Lists!$N$2:$N$8,MATCH(WEEKDAY(B4,2),Lists!$M$2:$M$8,0)) -> الثلاثاء | H4: الرياض | I4: =INDEX(Lists!$B$2:$B$6,MATCH(H4,Lists!$A$2:$A$6,0)) -> المنطقة الوسطى | J4: إكسسوارات | K4: حامل جوال للسيارة | L4: 149 | M4: 3 | N4: 0 | O4: نقدي | P4: فرد | Q4: عبدالله المطيري | R4: =L4*M4*(1-N4) -> 447
A5: ORD-00008 | B5: 45294 | C5: =YEAR(B5) -> 2024 | D5: =MONTH(B5) -> 1 | E5: =INDEX(Lists!$K$2:$K$13,MATCH(D5,Lists!$J$2:$J$13,0)) -> يناير | F5: ="Q"&ROUNDUP(D5/3,0) -> Q1 | G5: =INDEX(Lists!$N$2:$N$8,MATCH(WEEKDAY(B5,2),Lists!$M$2:$M$8,0)) -> الأربعاء | H5: مكة المكرمة | I5: =INDEX(Lists!$B$2:$B$6,MATCH(H5,Lists!$A$2:$A$6,0)) -> المنطقة الغربية | J5: إكسسوارات | K5: شاحن سريع 65 واط | L5: 259 | M5: 1 | N5: 0 | O5: بطاقة ائتمان | P5: فرد | Q5: تركي السبيعي | R5: =L5*M5*(1-N5) -> 259
A6: ORD-00006 | B6: 45294 | C6: =YEAR(B6) -> 2024 | D6: =MONTH(B6) -> 1 | E6: =INDEX(Lists!$K$2:$K$13,MATCH(D6,Lists!$J$2:$J$13,0)) -> يناير | F6: ="Q"&ROUNDUP(D6/3,0) -> Q1 | G6: =INDEX(Lists!$N$2:$N$8,MATCH(WEEKDAY(B6,2),Lists!$M$2:$M$8,0)) -> الأربعاء | H6: مكة المكرمة | I6: =INDEX(Lists!$B$2:$B$6,MATCH(H6,Lists!$A$2:$A$6,0)) -> المنطقة الغربية | J6: سماعات وصوتيات | K6: سماعة بلوتوث نوفا | L6: 179 | M6: 1 | N6: 0.15 | O6: نقدي | P6: فرد | Q6: خالد الشمري | R6: =L6*M6*(1-N6) -> 152.15
A7: ORD-00004 | B7: 45294 | C7: =YEAR(B7) -> 2024 | D7: =MONTH(B7) -> 1 | E7: =INDEX(Lists!$K$2:$K$13,MATCH(D7,Lists!$J$2:$J$13,0)) -> يناير | F7: ="Q"&ROUNDUP(D7/3,0) -> Q1 | G7: =INDEX(Lists!$N$2:$N$8,MATCH(WEEKDAY(B7,2),Lists!$M$2:$M$8,0)) -> الأربعاء | H7: جدة | I7: =INDEX(Lists!$B$2:$B$6,MATCH(H7,Lists!$A$2:$A$6,0)) -> المنطقة الغربية | J7: جوالات | K7: جوال نوفا لايت | L7: 3829 | M7: 2 | N7: 0 | O7: بطاقة ائتمان | P7: فرد | Q7: سارة القحطاني | R7: =L7*M7*(1-N7) -> 7658
A8: ORD-00005 | B8: 45294 | C8: =YEAR(B8) -> 2024 | D8: =MONTH(B8) -> 1 | E8: =INDEX(Lists!$K$2:$K$13,MATCH(D8,Lists!$J$2:$J$13,0)) -> يناير | F8: ="Q"&ROUNDUP(D8/3,0) -> Q1 | G8: =INDEX(Lists!$N$2:$N$8,MATCH(WEEKDAY(B8,2),Lists!$M$2:$M$8,0)) -> الأربعاء | H8: الرياض | I8: =INDEX(Lists!$B$2:$B$6,MATCH(H8,Lists!$A$2:$A$6,0)) -> المنطقة الوسطى | J8: إكسسوارات | K8: كابل شحن Type-C | L8: 159 | M8: 2 | N8: 0.15 | O8: تحويل بنكي | P8: فرد | Q8: محمد العتيبي | R8: =L8*M8*(1-N8) -> 270.3
A9: ORD-00007 | B9: 45294 | C9: =YEAR(B9) -> 2024 | D9: =MONTH(B9) -> 1 | E9: =INDEX(Lists!$K$2:$K$13,MATCH(D9,Lists!$J$2:$J$13,0)) -> يناير | F9: ="Q"&ROUNDUP(D9/3,0) -> Q1 | G9: =INDEX(Lists!$N$2:$N$8,MATCH(WEEKDAY(B9,2),Lists!$M$2:$M$8,0)) -> الأربعاء | H9: الرياض | I9: =INDEX(Lists!$B$2:$B$6,MATCH(H9,Lists!$A$2:$A$6,0)) -> المنطقة الوسطى | J9: جوالات | K9: جوال بولسار ميني | L9: 2139 | M9: 1 | N9: 0 | O9: بطاقة ائتمان | P9: فرد | Q9: منيرة الحربي | R9: =L9*M9*(1-N9) -> 2139
A10: ORD-00009 | B10: 45295 | C10: =YEAR(B10) -> 2024 | D10: =MONTH(B10) -> 1 | E10: =INDEX(Lists!$K$2:$K$13,MATCH(D10,Lists!$J$2:$J$13,0)) -> يناير | F10: ="Q"&ROUNDUP(D10/3,0) -> Q1 | G10: =INDEX(Lists!$N$2:$N$8,MATCH(WEEKDAY(B10,2),Lists!$M$2:$M$8,0)) -> الخميس | H10: جدة | I10: =INDEX(Lists!$B$2:$B$6,MATCH(H10,Lists!$A$2:$A$6,0)) -> المنطقة الغربية | J10: إكسسوارات | K10: كفر حماية بريميوم | L10: 39 | M10: 1 | N10: 0.05 | O10: بطاقة ائتمان | P10: فرد | Q10: سارة القحطاني | R10: =L10*M10*(1-N10) -> 37.05
A11: ORD-00010 | B11: 45295 | C11: =YEAR(B11) -> 2024 | D11: =MONTH(B11) -> 1 | E11: =INDEX(Lists!$K$2:$K$13,MATCH(D11,Lists!$J$2:$J$13,0)) -> يناير | F11: ="Q"&ROUNDUP(D11/3,0) -> Q1 | G11: =INDEX(Lists!$N$2:$N$8,MATCH(WEEKDAY(B11,2),Lists!$M$2:$M$8,0)) -> الخميس | H11: الرياض | I11: =INDEX(Lists!$B$2:$B$6,MATCH(H11,Lists!$A$2:$A$6,0)) -> المنطقة الوسطى | J11: جوالات | K11: جوال نوفا X12 | L11: 1199 | M11: 2 | N11: 0.05 | O11: نقدي | P11: فرد | Q11: محمد العتيبي | R11: =L11*M11*(1-N11) -> 2278.1
A12: ORD-00012 | B12: 45296 | C12: =YEAR(B12) -> 2024 | D12: =MONTH(B12) -> 1 | E12: =INDEX(Lists!$K$2:$K$13,MATCH(D12,Lists!$J$2:$J$13,0)) -> يناير | F12: ="Q"&ROUNDUP(D12/3,0) -> Q1 | G12: =INDEX(Lists!$N$2:$N$8,MATCH(WEEKDAY(B12,2),Lists!$M$2:$M$8,0)) -> الجمعة | H12: الدمام | I12: =INDEX(Lists!$B$2:$B$6,MATCH(H12,Lists!$A$2:$A$6,0)) -> المنطقة الشرقية | J12: سماعات وصوتيات | K12: سماعة رأس أوركا | L12: 569 | M12: 5 | N12: 0 | O12: تحويل بنكي | P12: شركة | Q12: عبدالله المطيري | R12: =L12*M12*(1-N12) -> 2845
A13: ORD-00013 | B13: 45296 | C13: =YEAR(B13) -> 2024 | D13: =MONTH(B13) -> 1 | E13: =INDEX(Lists!$K$2:$K$13,MATCH(D13,Lists!$J$2:$J$13,0)) -> يناير | F13: ="Q"&ROUNDUP(D13/3,0) -> Q1 | G13: =INDEX(Lists!$N$2:$N$8,MATCH(WEEKDAY(B13,2),Lists!$M$2:$M$8,0)) -> الجمعة | H13: مكة المكرمة | I13: =INDEX(Lists!$B$2:$B$6,MATCH(H13,Lists!$A$2:$A$6,0)) -> المنطقة الغربية | J13: سماعات وصوتيات | K13: سماعة رأس أوركا | L13: 419 | M13: 1 | N13: 0 | O13: تقسيط | P13: فرد | Q13: تركي السبيعي | R13: =L13*M13*(1-N13) -> 419
... A1121: ORD-01146 | B1121: 45657 | C1121: =YEAR(B1121) -> 2024 | D1121: =MONTH(B1121) -> 12 | E1121: =INDEX(Lists!$K$2:$K$13,MATCH(D1121,Lists!$J$2:$J$13,0)) -> ديسمبر | F1121: ="Q"&ROUNDUP(D1121/3,0) -> Q4 | G1121: =INDEX(Lists!$N$2:$N$8,MATCH(WEEKDAY(B1121,2),Lists!$M$2:$M$8,0)) -> الثلاثاء | H1121: جدة | I1121: =INDEX(Lists!$B$2:$B$6,MATCH(H1121,Lists!$A$2:$A$6,0)) -> المنطقة الغربية | J1121: أجهزة منزلية ذكية | K1121: مصباح ذكي | L1121: 499 | M1121: 10 | N1121: 0 | O1121: بطاقة ائتمان | P1121: شركة | Q1121: نورة الدوسري | R1121: =L1121*M1121*(1-N1121) -> 4990

Sheet Cleaning_Log
A1: سجل تنظيف ومعالجة البيانات
A2: توثيق كامل لخطوات تحويل البيانات من حالتها الخام إلى نسخة نظيفة جاهزة للتحليل
A4: ملخص عام
A5: عدد صفوف البيانات الخام | B5: =COUNTA(RawData[رقم الطلب]) -> 1196
A6: عدد صفوف البيانات بعد التنظيف | B6: =COUNTA(CleanData[رقم الطلب]) -> 1120
A7: عدد الصفوف التي تم استبعادها/دمجها أثناء التنظيف | B7: =B5-B6 -> 76
A8: نسبة البيانات المحتفظ بها من الأصل | B8: =B6/B5 -> 0.93645485
A11: جدول خطوات التنظيف التفصيلي
A12: # | B12: مشكلة البيانات المكتشفة | C12: العدد (معادلة حية على البيانات الخام) | D12: الإجراء الذي تم تنفيذه أثناء التنظيف
A13: 1 | B13: طلبات مكررة بالكامل (نفس رقم الطلب أُدخل أكثر من مرة) | C13: =COUNTIF(RawData[تكرار؟],"مكرر") -> 46 | D13: تم حذف التكرار والاحتفاظ بأول ظهور للطلب فقط (Order ID).
A14: 2 | B14: تواريخ مخزّنة كنص أو بصيغ غير موحدة (DD/MM/YYYY, YYYY-MM-DD, DD-MM-YYYY) | C14: =COUNTIF(RawData[تاريخ نصي؟],"نعم") -> 114 | D14: تم تحويل جميع صيغ التاريخ النصية إلى تاريخ Excel رقمي موحّد. من ضمنها 5 صفوف كانت بتواريخ غير صالحة فعليًا (مثل 31/02/2024) تعذّر تصحيحها فتم استبعادها بالكامل.
A15: 3 | B15: كمية غير منطقية (صفر أو قيمة سالبة) | C15: =COUNTIFS(RawData[الكمية],"<=0") -> 10 | D15: خطأ إدخال حرج لا يمكن تصحيحه بثقة (لا يمكن معرفة الكمية الصحيحة المقصودة) → تم حذف هذه الصفوف بالكامل.
A16: 4 | B16: أسعار وحدة شاذة (أعلى من 3 أضعاف متوسط سعر الفئة نفسها) | C16: =COUNTIF(RawData[سعر شاذ؟],"نعم") -> 8 | D16: غالبًا خطأ إدخال 'صفر إضافي' (Fat-finger) → تم تصحيح القيمة بقسمتها على 10 بعد مطابقتها مع نطاق أسعار الفئة.
A17: 5 | B17: نسبة خصم غير منطقية (خارج المدى المسموح 0% - 100%) | C17: =COUNTIFS(RawData[نسبة الخصم],"<0")+COUNTIFS(RawData[نسبة الخصم],">1") -> 4 | D17: تعذّر التأكد من النسبة الصحيحة المقصودة → تمت إعادة ضبطها إلى 0% (بدون خصم) ريثما تأكيد لاحق من الفرع.
A18: 6 | B18: قيم مفقودة في عمود الكمية | C18: =COUNTBLANK(RawData[الكمية]) -> 22 | D18: تمت التعبئة بالوسيط (Median) لكمية نفس الفئة، وهي طريقة تقلل أثر القيم المتطرفة مقارنة بالمتوسط الحسابي.
A19: 7 | B19: قيم مفقودة في عمود نسبة الخصم | C19: =COUNTBLANK(RawData[نسبة الخصم]) -> 30 | D19: تمت التعبئة بـ 0% على افتراض عدم منح خصم عند عدم تسجيله صراحة.
A20: 8 | B20: قيم مفقودة في عمود طريقة الدفع | C20: =COUNTBLANK(RawData[طريقة الدفع]) -> 12 | D20: تمت التعبئة بالقيمة الأكثر شيوعًا (المنوال) في البيانات: "بطاقة ائتمان".
A21: 9 | B21: قيم مفقودة في عمود نوع العميل | C21: =COUNTBLANK(RawData[نوع العميل]) -> 20 | D21: تمت التعبئة بالقيمة الأكثر شيوعًا (المنوال): "فرد".
A22: 10 | B22: قيم مفقودة في عمود الفرع | C22: =COUNTBLANK(RawData[الفرع]) -> 15 | D22: الفرع بُعد أساسي لا يمكن تخمينه بثقة من بقية الأعمدة → تم حذف هذه الصفوف بالكامل.
A23: 11 | B23: عدم اتساق نصي في أسماء الفروع وطرق الدفع (مسافات زائدة، اختلاف إملائي، مسميات إنجليزية) | C23: =SUMPRODUCT((RawData[الفرع]<>"")*ISNA(MATCH(RawData[الفرع],Lists!$A$2:$A$6,0)))+SUMPRODUCT((RawData[طريقة الدفع]<>"")*ISNA(MATCH(RawData[طريقة الدفع],Lists!$F$2:$F$5,0))) -> 84 | D23: تم توحيد جميع الاختلافات إلى تسمية قياسية واحدة لكل فرع وطريقة دفع (مثال: "جده"/"Jeddah"/" جدة " ← "جدة"), وإزالة المسافات الزائدة من كل الحقول النصية.
A25: ملاحظة منهجية: يظهر عمود 'العدد' نتيجة معادلات حية مرتبطة مباشرة بشيت 'Raw_Data' (وليست أرقامًا ثابتة)، بحيث لو تغيّرت بيانات المصدر الخام ستتحدث هذه الأعداد تلقائيًا. عملية التصحيح والدمج والحذف نفّذت مرة واحدة والنتيجة النهائية موثّقة في شيت 'Clean_Data'.

Sheet Raw_Data
A1: الرقم التسلسلي | B1: رقم الطلب | C1: تاريخ الطلب | D1: الفرع | E1: الفئة | F1: المنتج | G1: سعر الوحدة | H1: الكمية | I1: نسبة الخصم | J1: طريقة الدفع | K1: نوع العميل | L1: المندوب | M1: متوسط سعر الفئة | N1: سعر شاذ؟ | O1: تاريخ نصي؟ | P1: تكرار؟ | Q1: به قيمة مفقودة؟ | S1: ملاحظة: هذا الشيت يمثل البيانات كما وردت من نظام نقاط البيع دون أي تعديل، وتحتوي عمدًا على قيم مفقودة وتكرارات وأخطاء إدخال وتنسيقات تاريخ غير موحدة لغرض تنفيذ خطوات التنظيف الموثقة في شيت 'Cleaning_Log'. الأعمدة M إلى Q معادلات حية تكتشف المشاكل تلقائيًا.
A2: 1 | B2: ORD-00637 | C2: 45514 | D2: الرياض | E2: سماعات وصوتيات | F2: سماعة بلوتوث نوفا | G2: 729 | H2: 2 | I2: 0.15 | J2: تقسيط | K2: فرد | L2: لمى العنزي | M2: =AVERAGEIF($E$2:$E$1197,E2,$G$2:$G$1197) -> 545.35882 | N2: =IF(G2>M2*3,"نعم","لا") -> لا | O2: =IF(OR(C2="",ISNUMBER(C2)),"لا","نعم") -> لا | P2: =IF(COUNTIF($B$2:B2,B2)>1,"مكرر","فريد") -> فريد | Q2: =IF(COUNTBLANK(D2:L2)>0,"نعم","لا") -> لا
A3: 2 | B3: ORD-00244 | C3: 45378 | D3: الدمام | E3: أجهزة منزلية ذكية | F3: كاميرا مراقبة ذكية | G3: 589 | H3: 2 | I3: 0 | J3: بطاقة ائتمان | K3: فرد | L3: نورة الدوسري | M3: =AVERAGEIF($E$2:$E$1197,E3,$G$2:$G$1197) -> 366.30657 | N3: =IF(G3>M3*3,"نعم","لا") -> لا | O3: =IF(OR(C3="",ISNUMBER(C3)),"لا","نعم") -> لا | P3: =IF(COUNTIF($B$2:B3,B3)>1,"مكرر","فريد") -> فريد | Q3: =IF(COUNTBLANK(D3:L3)>0,"نعم","لا") -> لا
A4: 3 | B4: ORD-01014 | C4: 45620 | D4: جدة | E4: حواسيب محمولة | F4: لابتوب أوركا برو 15 | G4: 2979 | H4: 1 | I4: 0.05 | J4: بطاقة ائتمان | K4: فرد | L4: منيرة الحربي | M4: =AVERAGEIF($E$2:$E$1197,E4,$G$2:$G$1197) -> 4981.1456 | N4: =IF(G4>M4*3,"نعم","لا") -> لا | O4: =IF(OR(C4="",ISNUMBER(C4)),"لا","نعم") -> لا | P4: =IF(COUNTIF($B$2:B4,B4)>1,"مكرر","فريد") -> فريد | Q4: =IF(COUNTBLANK(D4:L4)>0,"نعم","لا") -> لا
A5: 4 | B5: ORD-01114 | C5: 45648 | D5: الرياض | E5: إكسسوارات | F5: حامل جوال للسيارة | G5: 169 | H5: 1 | I5: 0.05 | J5: تقسيط | K5: شركة | L5: ريم الزهراني | M5: =AVERAGEIF($E$2:$E$1197,E5,$G$2:$G$1197) -> 186.05629 | N5: =IF(G5>M5*3,"نعم","لا") -> لا | O5: =IF(OR(C5="",ISNUMBER(C5)),"لا","نعم") -> لا | P5: =IF(COUNTIF($B$2:B5,B5)>1,"مكرر","فريد") -> فريد | Q5: =IF(COUNTBLANK(D5:L5)>0,"نعم","لا") -> لا
A6: 5 | B6: ORD-00059 | C6: 45313 | D6: الرياض | E6: سماعات وصوتيات | F6: سماعة رياضية مقاومة للماء | G6: 269 | H6: 1 | I6: 0.15 | J6: نقدي | L6: فهد الغامدي | M6: =AVERAGEIF($E$2:$E$1197,E6,$G$2:$G$1197) -> 545.35882 | N6: =IF(G6>M6*3,"نعم","لا") -> لا | O6: =IF(OR(C6="",ISNUMBER(C6)),"لا","نعم") -> لا | P6: =IF(COUNTIF($B$2:B6,B6)>1,"مكرر","فريد") -> فريد | Q6: =IF(COUNTBLANK(D6:L6)>0,"نعم","لا") -> نعم
A7: 6 | B7: ORD-01023 | C7: 45622 | D7: الرياض | E7: جوالات | F7: جوال نوفا لايت | G7: 2519 | H7: 2 | I7: 0.15 | J7: نقدي | K7: فرد | L7: محمد العتيبي | M7: =AVERAGEIF($E$2:$E$1197,E7,$G$2:$G$1197) -> 2870.2677 | N7: =IF(G7>M7*3,"نعم","لا") -> لا | O7: =IF(OR(C7="",ISNUMBER(C7)),"لا","نعم") -> لا | P7: =IF(COUNTIF($B$2:B7,B7)>1,"مكرر","فريد") -> فريد | Q7: =IF(COUNTBLANK(D7:L7)>0,"نعم","لا") -> لا
A8: 7 | B8: ORD-00707 | C8: 45532 | D8: الرياض | E8: حواسيب محمولة | F8: لابتوب نوفا ألترا | G8: 2949 | H8: 5 | I8: 0.05 | J8: بطاقة ائتمان | K8: شركة | L8: سارة القحطاني | M8: =AVERAGEIF($E$2:$E$1197,E8,$G$2:$G$1197) -> 4981.1456 | N8: =IF(G8>M8*3,"نعم","لا") -> لا | O8: =IF(OR(C8="",ISNUMBER(C8)),"لا","نعم") -> لا | P8: =IF(COUNTIF($B$2:B8,B8)>1,"مكرر","فريد") -> فريد | Q8: =IF(COUNTBLANK(D8:L8)>0,"نعم","لا") -> لا
A9: 8 | B9: ORD-00627 | C9: 45511 | D9: جدة | E9: إكسسوارات | F9: كابل شحن Type-C | G9: 99 | H9: 2 | I9: 0.05 | J9: بطاقة ائتمان | K9: شركة | L9: نورة الدوسري | M9: =AVERAGEIF($E$2:$E$1197,E9,$G$2:$G$1197) -> 186.05629 | N9: =IF(G9>M9*3,"نعم","لا") -> لا | O9: =IF(OR(C9="",ISNUMBER(C9)),"لا","نعم") -> لا | P9: =IF(COUNTIF($B$2:B9,B9)>1,"مكرر","فريد") -> فريد | Q9: =IF(COUNTBLANK(D9:L9)>0,"نعم","لا") -> لا
A10: 9 | B10: ORD-00108 | C10: 45331 | D10: مكة المكرمة | E10: جوالات | F10: جوال أوركا الجديد | G10: 1279 | H10: 10 | I10: 0.15 | J10: تقسيط | K10: شركة | L10: منيرة الحربي | M10: =AVERAGEIF($E$2:$E$1197,E10,$G$2:$G$1197) -> 2870.2677 | N10: =IF(G10>M10*3,"نعم","لا") -> لا | O10: =IF(OR(C10="",ISNUMBER(C10)),"لا","نعم") -> لا | P10: =IF(COUNTIF($B$2:B10,B10)>1,"مكرر","فريد") -> فريد | Q10: =IF(COUNTBLANK(D10:L10)>0,"نعم","لا") -> لا
A11: 10 | B11: ORD-00583 | C11: 45498 | D11: الدمام | E11: سماعات وصوتيات | F11: سماعة رياضية مقاومة للماء | G11: 549 | H11: 1 | I11: 0.15 | J11: تقسيط | K11: فرد | L11: محمد العتيبي | M11: =AVERAGEIF($E$2:$E$1197,E11,$G$2:$G$1197) -> 545.35882 | N11: =IF(G11>M11*3,"نعم","لا") -> لا | O11: =IF(OR(C11="",ISNUMBER(C11)),"لا","نعم") -> لا | P11: =IF(COUNTIF($B$2:B11,B11)>1,"مكرر","فريد") -> فريد | Q11: =IF(COUNTBLANK(D11:L11)>0,"نعم","لا") -> لا
A12: 11 | B12: ORD-00571 | C12: 45496 | D12: جدة | E12: حواسيب محمولة | F12: لابتوب بولسار الأساسي | G12: 5729 | H12: 2 | I12: 0.15 | J12: تقسيط | K12: شركة | L12: ريم الزهراني | M12: =AVERAGEIF($E$2:$E$1197,E12,$G$2:$G$1197) -> 4981.1456 | N12: =IF(G12>M12*3,"نعم","لا") -> لا | O12: =IF(OR(C12="",ISNUMBER(C12)),"لا","نعم") -> لا | P12: =IF(COUNTIF($B$2:B12,B12)>1,"مكرر","فريد") -> فريد | Q12: =IF(COUNTBLANK(D12:L12)>0,"نعم","لا") -> لا
A13: 12 | B13: ORD-00045 | C13: 45308 | D13: جدة | E13: إكسسوارات | F13: كابل شحن Type-C | G13: 79 | H13: 1 | I13: 0 | J13: نقدي | K13: فرد | L13: فهد الغامدي | M13: =AVERAGEIF($E$2:$E$1197,E13,$G$2:$G$1197) -> 186.05629 | N13: =IF(G13>M13*3,"نعم","لا") -> لا | O13: =IF(OR(C13="",ISNUMBER(C13)),"لا","نعم") -> لا | P13: =IF(COUNTIF($B$2:B13,B13)>1,"مكرر","فريد") -> فريد | Q13: =IF(COUNTBLANK(D13:L13)>0,"نعم","لا") -> لا
A14: 13 | B14: ORD-00050 | C14: 45309 | D14: جدة | E14: أجهزة منزلية ذكية | F14: مصباح ذكي | G14: 449 | H14: 1 | I14: 0 | J14: نقدي | K14: فرد | L14: ريم الزهراني | M14: =AVERAGEIF($E$2:$E$1197,E14,$G$2:$G$1197) -> 366.30657 | N14: =IF(G14>M14*3,"نعم","لا") -> لا | O14: =IF(OR(C14="",ISNUMBER(C14)),"لا","نعم") -> لا | P14: =IF(COUNTIF($B$2:B14,B14)>1,"مكرر","فريد") -> فريد | Q14: =IF(COUNTBLANK(D14:L14)>0,"نعم","لا") -> لا
A15: 14 | B15: ORD-00603 | C15: 45506 | D15: الدمام | E15: جوالات | F15: جوال نوفا X12 | G15: 1309 | H15: 10 | I15: 0.05 | J15: بطاقة ائتمان | L15: محمد العتيبي | M15: =AVERAGEIF($E$2:$E$1197,E15,$G$2:$G$1197) -> 2870.2677 | N15: =IF(G15>M15*3,"نعم","لا") -> لا | O15: =IF(OR(C15="",ISNUMBER(C15)),"لا","نعم") -> لا | P15: =IF(COUNTIF($B$2:B15,B15)>1,"مكرر","فريد") -> فريد | Q15: =IF(COUNTBLANK(D15:L15)>0,"نعم","لا") -> نعم
A16: 15 | B16: ORD-00406 | C16: 45437 | D16: جدة | E16: حواسيب محمولة | F16: لابتوب نوفا بوك 14 | G16: 5449 | H16: 1 | I16: 0 | J16: بطاقة ائتمان | K16: شركة | L16: منيرة الحربي | M16: =AVERAGEIF($E$2:$E$1197,E16,$G$2:$G$1197) -> 4981.1456 | N16: =IF(G16>M16*3,"نعم","لا") -> لا | O16: =IF(OR(C16="",ISNUMBER(C16)),"لا","نعم") -> لا | P16: =IF(COUNTIF($B$2:B16,B16)>1,"مكرر","فريد") -> فريد | Q16: =IF(COUNTBLANK(D16:L16)>0,"نعم","لا") -> لا
A17: 16 | B17: ORD-00466 | C17: 45459 | D17: الدمام | E17: إكسسوارات | F17: شاحن سريع 65 واط | G17: 329 | H17: 2 | I17: 0.05 | J17: بطاقة ائتمان | K17: فرد | L17: لمى العنزي | M17: =AVERAGEIF($E$2:$E$1197,E17,$G$2:$G$1197) -> 186.05629 | N17: =IF(G17>M17*3,"نعم","لا") -> لا | O17: =IF(OR(C17="",ISNUMBER(C17)),"لا","نعم") -> لا | P17: =IF(COUNTIF($B$2:B17,B17)>1,"مكرر","فريد") -> فريد | Q17: =IF(COUNTBLANK(D17:L17)>0,"نعم","لا") -> لا
A18: 17 | B18: ORD-00761 | C18: 15-09-2024 | D18: الرياض | E18: إكسسوارات | F18: باور بانك 20000 | G18: 169 | H18: 1 | I18: 0.1 | J18: تقسيط | K18: فرد | L18: سارة القحطاني | M18: =AVERAGEIF($E$2:$E$1197,E18,$G$2:$G$1197) -> 186.05629 | N18: =IF(G18>M18*3,"نعم","لا") -> لا | O18: =IF(OR(C18="",ISNUMBER(C18)),"لا","نعم") -> نعم | P18: =IF(COUNTIF($B$2:B18,B18)>1,"مكرر","فريد") -> فريد | Q18: =IF(COUNTBLANK(D18:L18)>0,"نعم","لا") -> لا
A19: 18 | B19: ORD-00210 | C19: 45368 | D19: مكه المكرمة | E19: حواسيب محمولة | F19: لابتوب نوفا ألترا | G19: 4549 | H19: 1 | I19: 0.1 | J19: نقدي | K19: فرد | L19: نورة الدوسري | M19: =AVERAGEIF($E$2:$E$1197,E19,$G$2:$G$1197) -> 4981.1456 | N19: =IF(G19>M19*3,"نعم","لا") -> لا | O19: =IF(OR(C19="",ISNUMBER(C19)),"لا","نعم") -> لا | P19: =IF(COUNTIF($B$2:B19,B19)>1,"مكرر","فريد") -> فريد | Q19: =IF(COUNTBLANK(D19:L19)>0,"نعم","لا") -> لا
A20: 19 | B20: ORD-00722 | C20: 45535 | D20: جدة | E20: جوالات | F20: جوال بولسار ميني | G20: 2019 | H20: 2 | I20: 0.1 | J20: تقسيط | K20: فرد | L20: عبدالله المطيري | M20: =AVERAGEIF($E$2:$E$1197,E20,$G$2:$G$1197) -> 2870.2677 | N20: =IF(G20>M20*3,"نعم","لا") -> لا | O20: =IF(OR(C20="",ISNUMBER(C20)),"لا","نعم") -> لا | P20: =IF(COUNTIF($B$2:B20,B20)>1,"مكرر","فريد") -> فريد | Q20: =IF(COUNTBLANK(D20:L20)>0,"نعم","لا") -> لا
A21: 20 | B21: ORD-00902 | C21: 45596 | D21: الرياض | E21: حواسيب محمولة | F21: لابتوب بولسار الأساسي | G21: 6809 | H21: 3 | I21: 0.05 | J21: بطاقة ائتمان | K21: شركة | L21: ريم الزهراني | M21: =AVERAGEIF($E$2:$E$1197,E21,$G$2:$G$1197) -> 4981.1456 | N21: =IF(G21>M21*3,"نعم","لا") -> لا | O21: =IF(OR(C21="",ISNUMBER(C21)),"لا","نعم") -> لا | P21: =IF(COUNTIF($B$2:B21,B21)>1,"مكرر","فريد") -> فريد | Q21: =IF(COUNTBLANK(D21:L21)>0,"نعم","لا") -> لا
A22: 21 | B22: ORD-00169 | C22: 45357 | D22: جدة | E22: إكسسوارات | F22: كابل شحن Type-C | G22: 59 | H22: 6 | I22: 0.05 | J22: تحويل بنكي | K22: شركة | L22: نورة الدوسري | M22: =AVERAGEIF($E$2:$E$1197,E22,$G$2:$G$1197) -> 186.05629 | N22: =IF(G22>M22*3,"نعم","لا") -> لا | O22: =IF(OR(C22="",ISNUMBER(C22)),"لا","نعم") -> لا | P22: =IF(COUNTIF($B$2:B22,B22)>1,"مكرر","فريد") -> فريد | Q22: =IF(COUNTBLANK(D22:L22)>0,"نعم","لا") -> لا
A23: 22 | B23: ORD-00947 | C23: 45605 | D23: الرياض | E23: سماعات وصوتيات | F23: سماعة رياضية مقاومة للماء | G23: 489 | H23: 1 | I23: 0.05 | J23: بطاقة ائتمان | K23: فرد | L23: تركي السبيعي | M23: =AVERAGEIF($E$2:$E$1197,E23,$G$2:$G$1197) -> 545.35882 | N23: =IF(G23>M23*3,"نعم","لا") -> لا | O23: =IF(OR(C23="",ISNUMBER(C23)),"لا","نعم") -> لا | P23: =IF(COUNTIF($B$2:B23,B23)>1,"مكرر","فريد") -> فريد | Q23: =IF(COUNTBLANK(D23:L23)>0,"نعم","لا") -> لا
A24: 23 | B24: ORD-00837 | C24: 45575 | D24: جدة | E24: جوالات | F24: جوال أوركا برو | G24: 1509 | H24: 5 | I24: 0.15 | J24: بطاقة ائتمان | L24: ريم الزهراني | M24: =AVERAGEIF($E$2:$E$1197,E24,$G$2:$G$1197) -> 2870.2677 | N24: =IF(G24>M24*3,"نعم","لا") -> لا | O24: =IF(OR(C24="",ISNUMBER(C24)),"لا","نعم") -> لا | P24: =IF(COUNTIF($B$2:B24,B24)>1,"مكرر","فريد") -> فريد | Q24: =IF(COUNTBLANK(D24:L24)>0,"نعم","لا") -> نعم
A25: 24 | B25: ORD-00324 | C25: 45409 | D25: مكة المكرمة | E25: إكسسوارات | F25: شاحن سريع 65 واط | G25: 139 | H25: 1 | I25: 0 | J25: نقدي | K25: فرد | L25: ريم الزهراني | M25: =AVERAGEIF($E$2:$E$1197,E25,$G$2:$G$1197) -> 186.05629 | N25: =IF(G25>M25*3,"نعم","لا") -> لا | O25: =IF(OR(C25="",ISNUMBER(C25)),"لا","نعم") -> لا | P25: =IF(COUNTIF($B$2:B25,B25)>1,"مكرر","فريد") -> فريد | Q25: =IF(COUNTBLANK(D25:L25)>0,"نعم","لا") -> لا
A26: 25 | B26: ORD-00426 | C26: 45446 | D26: مكة المكرمة | E26: حواسيب محمولة | F26: لابتوب بولسار الأساسي | G26: 5379 | H26: 1 | I26: 0.15 | J26: تحويل بنكي | K26: فرد | L26: تركي السبيعي | M26: =AVERAGEIF($E$2:$E$1197,E26,$G$2:$G$1197) -> 4981.1456 | N26: =IF(G26>M26*3,"نعم","لا") -> لا | O26: =IF(OR(C26="",ISNUMBER(C26)),"لا","نعم") -> لا | P26: =IF(COUNTIF($B$2:B26,B26)>1,"مكرر","فريد") -> فريد | Q26: =IF(COUNTBLANK(D26:L26)>0,"نعم","لا") -> لا
A27: 26 | B27: ORD-00528 | C27: 45481 | D27: الرياض | E27: جوالات | F27: جوال نوفا X12 | G27: 2029 | H27: 2 | I27: 0.2 | J27: نقدي | K27: شركة | L27: سارة القحطاني | M27: =AVERAGEIF($E$2:$E$1197,E27,$G$2:$G$1197) -> 2870.2677 | N27: =IF(G27>M27*3,"نعم","لا") -> لا | O27: =IF(OR(C27="",ISNUMBER(C27)),"لا","نعم") -> لا | P27: =IF(COUNTIF($B$2:B27,B27)>1,"مكرر","فريد") -> فريد | Q27: =IF(COUNTBLANK(D27:L27)>0,"نعم","لا") -> لا
A28: 27 | B28: ORD-00129 | C28: 45340 | D28: المدينة المنورة | E28: حواسيب محمولة | F28: لابتوب نوفا ألترا | G28: 1849 | H28: 1 | I28: 0.05 | J28: بطاقة ائتمان | K28: فرد | L28: خالد الشمري | M28: =AVERAGEIF($E$2:$E$1197,E28,$G$2:$G$1197) -> 4981.1456 | N28: =IF(G28>M28*3,"نعم","لا") -> لا | O28: =IF(OR(C28="",ISNUMBER(C28)),"لا","نعم") -> لا | P28: =IF(COUNTIF($B$2:B28,B28)>1,"مكرر","فريد") -> فريد | Q28: =IF(COUNTBLANK(D28:L28)>0,"نعم","لا") -> لا
A29: 28 | B29: ORD-00567 | C29: 45495 | D29: جدة | E29: إكسسوارات | F29: باور بانك 20000 | G29: 79 | H29: 1 | I29: 0.05 | J29: بطاقة ائتمان | K29: فرد | L29: عبدالله المطيري | M29: =AVERAGEIF($E$2:$E$1197,E29,$G$2:$G$1197) -> 186.05629 | N29: =IF(G29>M29*3,"نعم","لا") -> لا | O29: =IF(OR(C29="",ISNUMBER(C29)),"لا","نعم") -> لا | P29: =IF(COUNTIF($B$2:B29,B29)>1,"مكرر","فريد") -> فريد | Q29: =IF(COUNTBLANK(D29:L29)>0,"نعم","لا") -> لا
A30: 29 | B30: ORD-01113 | C30: 45647 | D30: الرياض | E30: إكسسوارات | F30: كفر حماية بريميوم | G30: 139 | H30: 1 | I30: 0 | J30: بطاقة ائتمان | K30: فرد | L30: فهد الغامدي | M30: =AVERAGEIF($E$2:$E$1197,E30,$G$2:$G$1197) -> 186.05629 | N30: =IF(G30>M30*3,"نعم","لا") -> لا | O30: =IF(OR(C30="",ISNUMBER(C30)),"لا","نعم") -> لا | P30: =IF(COUNTIF($B$2:B30,B30)>1,"مكرر","فريد") -> فريد | Q30: =IF(COUNTBLANK(D30:L30)>0,"نعم","لا") -> لا
A31: 30 | B31: ORD-00410 | C31: 45438 | D31: مكة المكرمة | E31: حواسيب محمولة | F31: لابتوب نوفا بوك 14 | G31: 3669 | H31: 2 | I31: 0 | J31: بطاقة ائتمان | K31: فرد | L31: ريم الزهراني | M31: =AVERAGEIF($E$2:$E$1197,E31,$G$2:$G$1197) -> 4981.1456 | N31: =IF(G31>M31*3,"نعم","لا") -> لا | O31: =IF(OR(C31="",ISNUMBER(C31)),"لا","نعم") -> لا | P31: =IF(COUNTIF($B$2:B31,B31)>1,"مكرر","فريد") -> فريد | Q31: =IF(COUNTBLANK(D31:L31)>0,"نعم","لا") -> لا
A32: 31 | B32: ORD-00989 | C32: 18/11/2024 | D32: الرياض | E32: جوالات | F32: جوال أوركا الجديد | G32: 2859 | H32: 5 | I32: 0.05 | J32: بطاقة ائتمان | K32: شركة | L32: منيرة الحربي | M32: =AVERAGEIF($E$2:$E$1197,E32,$G$2:$G$1197) -> 2870.2677 | N32: =IF(G32>M32*3,"نعم","لا") -> لا | O32: =IF(OR(C32="",ISNUMBER(C32)),"لا","نعم") -> نعم | P32: =IF(COUNTIF($B$2:B32,B32)>1,"مكرر","فريد") -> فريد | Q32: =IF(COUNTBLANK(D32:L32)>0,"نعم","لا") -> لا
A33: 32 | B33: ORD-00157 | C33: 45353 | D33: الرياض | E33: أجهزة منزلية ذكية | F33: مقبس كهرباء ذكي | G33: 129 | H33: 2 | I33: 0 | J33: نقدي | K33: فرد | L33: عبدالله المطيري | M33: =AVERAGEIF($E$2:$E$1197,E33,$G$2:$G$1197) -> 366.30657 | N33: =IF(G33>M33*3,"نعم","لا") -> لا | O33: =IF(OR(C33="",ISNUMBER(C33)),"لا","نعم") -> لا | P33: =IF(COUNTIF($B$2:B33,B33)>1,"مكرر","فريد") -> فريد | Q33: =IF(COUNTBLANK(D33:L33)>0,"نعم","لا") -> لا
A34: 33 | B34: ORD-00921 | C34: 45601 | D34: المدينة المنورة | E34: جوالات | F34: جوال أوركا الجديد | G34: 4119 | H34: 3 | I34: 0 | J34: تقسيط | K34: فرد | L34: عبدالله المطيري | M34: =AVERAGEIF($E$2:$E$1197,E34,$G$2:$G$1197) -> 2870.2677 | N34: =IF(G34>M34*3,"نعم","لا") -> لا | O34: =IF(OR(C34="",ISNUMBER(C34)),"لا","نعم") -> لا | P34: =IF(COUNTIF($B$2:B34,B34)>1,"مكرر","فريد") -> فريد | Q34: =IF(COUNTBLANK(D34:L34)>0,"نعم","لا") -> لا
A35: 34 | B35: ORD-00696 | C35: 25/08/2024 | D35: جدة | E35: جوالات | F35: جوال أوركا الجديد | G35: 1189 | H35: 1 | I35: 0.05 | J35: نقدي | K35: فرد | L35: عبدالله المطيري | M35: =AVERAGEIF($E$2:$E$1197,E35,$G$2:$G$1197) -> 2870.2677 | N35: =IF(G35>M35*3,"نعم","لا") -> لا | O35: =IF(OR(C35="",ISNUMBER(C35)),"لا","نعم") -> نعم | P35: =IF(COUNTIF($B$2:B35,B35)>1,"مكرر","فريد") -> فريد | Q35: =IF(COUNTBLANK(D35:L35)>0,"نعم","لا") -> لا
A36: 35 | B36: ORD-01144 | C36: 45656 | D36: جدة | E36: جوالات | F36: جوال أوركا الجديد | G36: 1969 | H36: 1 | I36: 0 | J36: تحويل بنكي | K36: فرد | L36: سارة القحطاني | M36: =AVERAGEIF($E$2:$E$1197,E36,$G$2:$G$1197) -> 2870.2677 | N36: =IF(G36>M36*3,"نعم","لا") -> لا | O36: =IF(OR(C36="",ISNUMBER(C36)),"لا","نعم") -> لا | P36: =IF(COUNTIF($B$2:B36,B36)>1,"مكرر","فريد") -> فريد | Q36: =IF(COUNTBLANK(D36:L36)>0,"نعم","لا") -> لا
A37: 36 | B37: ORD-00136 | C37: 45342 | D37: الدمام | E37: حواسيب محمولة | F37: لابتوب نوفا بوك 14 | G37: 7189 | H37: 1 | I37: 0 | J37: تحويل بنكي | K37: فرد | L37: محمد العتيبي | M37: =AVERAGEIF($E$2:$E$1197,E37,$G$2:$G$1197) -> 4981.1456 | N37: =IF(G37>M37*3,"نعم","لا") -> لا | O37: =IF(OR(C37="",ISNUMBER(C37)),"لا","نعم") -> لا | P37: =IF(COUNTIF($B$2:B37,B37)>1,"مكرر","فريد") -> فريد | Q37: =IF(COUNTBLANK(D37:L37)>0,"نعم","لا") -> لا
A38: 37 | B38: ORD-00802 | C38: 29-09-2024 | D38: المدينة المنورة | E38: جوالات | F38: جوال بولسار ميني | G38: 1819 | H38: 1 | I38: 0 | J38: تحويل بنكي | K38: فرد | L38: فهد الغامدي | M38: =AVERAGEIF($E$2:$E$1197,E38,$G$2:$G$1197) -> 2870.2677 | N38: =IF(G38>M38*3,"نعم","لا") -> لا | O38: =IF(OR(C38="",ISNUMBER(C38)),"لا","نعم") -> نعم | P38: =IF(COUNTIF($B$2:B38,B38)>1,"مكرر","فريد") -> فريد | Q38: =IF(COUNTBLANK(D38:L38)>0,"نعم","لا") -> لا
A39: 38 | B39: ORD-00071 | C39: 45317 | D39: الدمام | E39: إكسسوارات | F39: حامل جوال للسيارة | G39: 69 | H39: 1 | I39: 0 | J39: بطاقة ائتمان | K39: فرد | L39: نورة الدوسري | M39: =AVERAGEIF($E$2:$E$1197,E39,$G$2:$G$1197) -> 186.05629 | N39: =IF(G39>M39*3,"نعم","لا") -> لا | O39: =IF(OR(C39="",ISNUMBER(C39)),"لا","نعم") -> لا | P39: =IF(COUNTIF($B$2:B39,B39)>1,"مكرر","فريد") -> فريد | Q39: =IF(COUNTBLANK(D39:L39)>0,"نعم","لا") -> لا
A40: 39 | B40: ORD-00320 | C40: 45406 | D40: الرياض | E40: جوالات | F40: جوال نوفا X12 | G40: 1409 | H40: 2 | I40: 0.15 | J40: تحويل بنكي | K40: فرد | L40: سارة القحطاني | M40: =AVERAGEIF($E$2:$E$1197,E40,$G$2:$G$1197) -> 2870.2677 | N40: =IF(G40>M40*3,"نعم","لا") -> لا | O40: =IF(OR(C40="",ISNUMBER(C40)),"لا","نعم") -> لا | P40: =IF(COUNTIF($B$2:B40,B40)>1,"مكرر","فريد") -> فريد | Q40: =IF(COUNTBLANK(D40:L40)>0,"نعم","لا") -> لا
...

Sheet Lists
A1: الفرع | B1: المنطقة | D1: الفئة | F1: طريقة الدفع | H1: نوع العميل | J1: رقم الشهر | K1: اسم الشهر | M1: رقم اليوم | N1: اسم اليوم | P1: المندوب | R1: المنطقة (فريدة) | T1: فلتر_المنطقة | V1: فلتر_الفئة
A2: الرياض | B2: المنطقة الوسطى | D2: جوالات | F2: بطاقة ائتمان | H2: فرد | J2: 1 | K2: يناير | M2: 1 | N2: الإثنين | P2: تركي السبيعي | R2: المنطقة الوسطى | T2: الكل | V2: الكل
A3: جدة | B3: المنطقة الغربية | D3: حواسيب محمولة | F3: نقدي | H3: شركة | J3: 2 | K3: فبراير | M3: 2 | N3: الثلاثاء | P3: خالد الشمري | R3: المنطقة الغربية | T3: المنطقة الوسطى | V3: جوالات
A4: الدمام | B4: المنطقة الشرقية | D4: إكسسوارات | F4: تقسيط | J4: 3 | K4: مارس | M4: 3 | N4: الأربعاء | P4: ريم الزهراني | R4: المنطقة الشرقية | T4: المنطقة الغربية | V4: حواسيب محمولة
A5: مكة المكرمة | B5: المنطقة الغربية | D5: أجهزة منزلية ذكية | F5: تحويل بنكي | J5: 4 | K5: أبريل | M5: 4 | N5: الخميس | P5: سارة القحطاني | T5: المنطقة الشرقية | V5: إكسسوارات
A6: المدينة المنورة | B6: المنطقة الغربية | D6: سماعات وصوتيات | J6: 5 | K6: مايو | M6: 5 | N6: الجمعة | P6: عبدالله المطيري | V6: أجهزة منزلية ذكية
J7: 6 | K7: يونيو | M7: 6 | N7: السبت | P7: فهد الغامدي | V7: سماعات وصوتيات
J8: 7 | K8: يوليو | M8: 7 | N8: الأحد | P8: لمى العنزي
J9: 8 | K9: أغسطس | P9: محمد العتيبي
J10: 9 | K10: سبتمبر | P10: منيرة الحربي
J11: 10 | K11: أكتوبر | P11: نورة الدوسري
J12: 11 | K12: نوفمبر
J13: 12 | K13: ديسمبر
